Workbook

Sheet 1_Panduan
A1: PANDUAN PENGGUNAAN WORKBOOK
A3: Urutan membaca saat presentasi
A4: Sheet | B4: Fungsi
A5: 2_Ringkasan | B5: HALAMAN PRESENTASI. Buka sheet ini di layar. Berisi posisi harga SKU kunci, angka utama, tiga hal yang perlu keputusan, dan peringatan kualitas data.
A6: 4_Matriks_Segmen | B6: Peta portofolio. Tunjukkan di mana ada SKU dan di mana kosong — per tipe pintu, band kapasitas, dan material pintu.
A7: 5_Harga_Channel | B7: Konsistensi harga antar channel modern dan tradisional, plus status kelengkapan pengumpulan data.
A8: 3_Master_Benchmark | B8: Data mentah tingkat SKU. Buka hanya jika ada yang bertanya detail. Semua sheet lain menarik angka dari sini.
A9: 6_Referensi | B9: Daftar nilai baku untuk dropdown dan parameter acuan indeks harga.
A12: Legenda warna sel
A13: Warna | B13: Nama | C13: Arti
B14: Kuning | C14: Sel input — diisi manual oleh tim. Ini satu-satunya sel yang boleh diketik.
B15: Hijau | C15: Sel hasil rumus utama (harga rata-rata, Rp/liter, indeks). Jangan ditimpa.
B16: Oranye | C16: Nilai ASUMSI yang belum diverifikasi. Wajib dicek sebelum dipakai mengambil keputusan.
B17: Biru muda | C17: Baris brand sendiri (Haier / AQUA) — untuk memudahkan mata saat presentasi.
B18: Abu-abu | C18: Label baris / header sekunder.
A21: Logika segmentasi yang dipakai (sesuai kesepakatan tim)
A22: Sumbu | B22: Definisi & alasan
A23: Sumbu 1 — Tipe Pintu | B23: 1 Pintu, 2 Pintu, Side-by-Side, Multi-Door 4 Pintu, Multi-Door 5 Pintu. Teknologi inverter umumnya mulai dari kelas di atas 2 pintu; kelas 2 pintu punya varian inverter dan non-inverter.
A24: Sumbu 2 — Kapasitas | B24: Dipecah per 50 liter. Kelas 1 pintu mulai dari sekitar 126 L. Kelas side-by-side mulai dari 400 L. Band diperluas hingga 700 L ke atas untuk menampung SKU jumbo terbaru.
A25: Sumbu 3 — Material Pintu | B25: Metal dan Glass. Ini bukan sekadar spesifikasi: material menentukan apakah kulkas cocok dipajang di dapur terbuka atau bahkan terlihat dari ruang tamu — jadi ini sumbu keputusan konsumen, bukan sumbu teknis.
A26: Sumbu 4 — Customer Need | B26: Setiap SKU diberi label job-to-be-done. Benchmark dimulai dari kebutuhan pasar, baru turun ke harga — bukan sebaliknya.
A27: Sumbu 5 — Channel | B27: Modern (UFO, Hartono) vs Tradisional (Candi Bantas Pos, Pondok Elektronik) vs Online. Harga tidak boleh dirata-rata lintas channel tanpa melihat spread-nya.
A30: Cara memperbarui data
A31: 1. Buka 3_Master_Benchmark. Isi hanya sel berwarna kuning (harga per channel, kapasitas, material pintu).
A32: 2. Untuk SKU baru, tambahkan baris di bawah baris terakhir, lalu salin rumus kolom G, Q sampai W dari baris di atasnya.
A33: 3. Perbarui kolom 'Tanggal Update' dan 'Sumber / Catatan' setiap kali mengubah harga. Tanpa jejak sumber, angka tidak bisa dipertanggungjawabkan di rapat.
A34: 4. Ubah status dari 'Asumsi - perlu cek' menjadi 'Terverifikasi' hanya setelah dikonfirmasi ke sumber resmi atau survei toko langsung.
A35: 5. Sheet 2, 4, dan 5 akan ikut terbarui otomatis. Tidak perlu diubah manual.
A36: 6. Frekuensi yang disarankan: mingguan, dengan pencatatan tambahan saat Harbolnas, Ramadan, dan periode pameran seperti Jakarta Fair.
A39: Disusun sebagai kerangka kerja benchmark. Seluruh angka harga bersumber dari listing ritel publik dan rilis pers, bukan data penjualan internal atau panel berbayar (GfK/MarketHac).

Sheet 2_Ringkasan
A1: BENCHMARK KULKAS INDONESIA — RINGKASAN UNTUK MANAJEMEN
A2: Fokus: posisi Haier Horizon Collection terhadap pesaing utama | Data per 4 Agustus 2026 | Halaman ini terhitung otomatis
A4: A. POSISI HARGA HAIER vs PESAING — SKU KUNCI
A5: Rp/Liter adalah metrik pembanding utama karena menetralkan perbedaan kapasitas. Indeks 100 = setara Sharp SJ-IF91PG-GB.
A6: Brand | B6: Kode Model | C6: Tipe Pintu | D6: Kapasitas (L) | E6: Harga Rata-rata (Rp) | F6: Rp per Liter | G6: Indeks (Acuan=100)
A7: {=IFERROR(INDEX('3_Master_Benchmark'!$B$5:$B$46,MATCH($B7,'3_Master_Benchmark'!$C$5:$C$46,0)),"")} -> Haier | B7: HRF-CTD729RITA(BK)U1 | C7: {=IFERROR(INDEX('3_Master_Benchmark'!$E$5:$E$46,MATCH($B7,'3_Master_Benchmark'!$C$5:$C$46,0)),"")} -> Multi-Door (4 Pintu) | D7: {=IFERROR(INDEX('3_Master_Benchmark'!$F$5:$F$46,MATCH($B7,'3_Master_Benchmark'!$C$5:$C$46,0)),"")} -> 650 | E7: {=IFERROR(INDEX('3_Master_Benchmark'!$P$5:$P$46,MATCH($B7,'3_Master_Benchmark'!$C$5:$C$46,0)),"")} | F7: {=IFERROR(INDEX(#REF!,MATCH($B7,'3_Master_Benchmark'!$C$5:$C$46,0)),"")} | G7: {=IFERROR(INDEX(#REF!,MATCH($B7,'3_Master_Benchmark'!$C$5:$C$46,0)),"")}
A8: {=IFERROR(INDEX('3_Master_Benchmark'!$B$5:$B$46,MATCH($B8,'3_Master_Benchmark'!$C$5:$C$46,0)),"")} -> Haier | B8: HRF-CTD779RSA(BK)U1 | C8: {=IFERROR(INDEX('3_Master_Benchmark'!$E$5:$E$46,MATCH($B8,'3_Master_Benchmark'!$C$5:$C$46,0)),"")} -> Multi-Door (4 Pintu) | D8: {=IFERROR(INDEX('3_Master_Benchmark'!$F$5:$F$46,MATCH($B8,'3_Master_Benchmark'!$C$5:$C$46,0)),"")} -> 700 | E8: {=IFERROR(INDEX('3_Master_Benchmark'!$P$5:$P$46,MATCH($B8,'3_Master_Benchmark'!$C$5:$C$46,0)),"")} | F8: {=IFERROR(INDEX(#REF!,MATCH($B8,'3_Master_Benchmark'!$C$5:$C$46,0)),"")} | G8: {=IFERROR(INDEX(#REF!,MATCH($B8,'3_Master_Benchmark'!$C$5:$C$46,0)),"")}
A9: {=IFERROR(INDEX('3_Master_Benchmark'!$B$5:$B$46,MATCH($B9,'3_Master_Benchmark'!$C$5:$C$46,0)),"")} -> Haier | B9: HRF-CTD779RAA(BK) | C9: {=IFERROR(INDEX('3_Master_Benchmark'!$E$5:$E$46,MATCH($B9,'3_Master_Benchmark'!$C$5:$C$46,0)),"")} -> Multi-Door (4 Pintu) | D9: {=IFERROR(INDEX('3_Master_Benchmark'!$F$5:$F$46,MATCH($B9,'3_Master_Benchmark'!$C$5:$C$46,0)),"")} -> 700 | E9: {=IFERROR(INDEX('3_Master_Benchmark'!$P$5:$P$46,MATCH($B9,'3_Master_Benchmark'!$C$5:$C$46,0)),"")} | F9: {=IFERROR(INDEX(#REF!,MATCH($B9,'3_Master_Benchmark'!$C$5:$C$46,0)),"")} | G9: {=IFERROR(INDEX(#REF!,MATCH($B9,'3_Master_Benchmark'!$C$5:$C$46,0)),"")}
A10: {=IFERROR(INDEX('3_Master_Benchmark'!$B$5:$B$46,MATCH($B10,'3_Master_Benchmark'!$C$5:$C$46,0)),"")} -> Haier | B10: HRF-CTD579RAG(BK) | C10: {=IFERROR(INDEX('3_Master_Benchmark'!$E$5:$E$46,MATCH($B10,'3_Master_Benchmark'!$C$5:$C$46,0)),"")} -> Multi-Door (4 Pintu) | D10: {=IFERROR(INDEX('3_Master_Benchmark'!$F$5:$F$46,MATCH($B10,'3_Master_Benchmark'!$C$5:$C$46,0)),"")} -> 502 | E10: {=IFERROR(INDEX('3_Master_Benchmark'!$P$5:$P$46,MATCH($B10,'3_Master_Benchmark'!$C$5:$C$46,0)),"")} | F10: {=IFERROR(INDEX(#REF!,MATCH($B10,'3_Master_Benchmark'!$C$5:$C$46,0)),"")} | G10: {=IFERROR(INDEX(#REF!,MATCH($B10,'3_Master_Benchmark'!$C$5:$C$46,0)),"")}
A11: {=IFERROR(INDEX('3_Master_Benchmark'!$B$5:$B$46,MATCH($B11,'3_Master_Benchmark'!$C$5:$C$46,0)),"")} -> Sharp | B11: SJ-IF91PG-GB | C11: {=IFERROR(INDEX('3_Master_Benchmark'!$E$5:$E$46,MATCH($B11,'3_Master_Benchmark'!$C$5:$C$46,0)),"")} -> Multi-Door (4 Pintu) | D11: {=IFERROR(INDEX('3_Master_Benchmark'!$F$5:$F$46,MATCH($B11,'3_Master_Benchmark'!$C$5:$C$46,0)),"")} -> 639 | E11: {=IFERROR(INDEX('3_Master_Benchmark'!$P$5:$P$46,MATCH($B11,'3_Master_Benchmark'!$C$5:$C$46,0)),"")} -> 18599000 | F11: {=IFERROR(INDEX(#REF!,MATCH($B11,'3_Master_Benchmark'!$C$5:$C$46,0)),"")} | G11: {=IFERROR(INDEX(#REF!,MATCH($B11,'3_Master_Benchmark'!$C$5:$C$46,0)),"")}
A12: {=IFERROR(INDEX('3_Master_Benchmark'!$B$5:$B$46,MATCH($B12,'3_Master_Benchmark'!$C$5:$C$46,0)),"")} -> LG | B12: GC-B257SQYL | C12: {=IFERROR(INDEX('3_Master_Benchmark'!$E$5:$E$46,MATCH($B12,'3_Master_Benchmark'!$C$5:$C$46,0)),"")} -> Side-by-Side | D12: {=IFERROR(INDEX('3_Master_Benchmark'!$F$5:$F$46,MATCH($B12,'3_Master_Benchmark'!$C$5:$C$46,0)),"")} -> 694 | E12: {=IFERROR(INDEX('3_Master_Benchmark'!$P$5:$P$46,MATCH($B12,'3_Master_Benchmark'!$C$5:$C$46,0)),"")} -> 12029000 | F12: {=IFERROR(INDEX(#REF!,MATCH($B12,'3_Master_Benchmark'!$C$5:$C$46,0)),"")} | G12: {=IFERROR(INDEX(#REF!,MATCH($B12,'3_Master_Benchmark'!$C$5:$C$46,0)),"")}
A13: {=IFERROR(INDEX('3_Master_Benchmark'!$B$5:$B$46,MATCH($B13,'3_Master_Benchmark'!$C$5:$C$46,0)),"")} -> Samsung | B13: RS90F65DNFSE | C13: {=IFERROR(INDEX('3_Master_Benchmark'!$E$5:$E$46,MATCH($B13,'3_Master_Benchmark'!$C$5:$C$46,0)),"")} -> Side-by-Side | D13: {=IFERROR(INDEX('3_Master_Benchmark'!$F$5:$F$46,MATCH($B13,'3_Master_Benchmark'!$C$5:$C$46,0)),"")} -> 641 | E13: {=IFERROR(INDEX('3_Master_Benchmark'!$P$5:$P$46,MATCH($B13,'3_Master_Benchmark'!$C$5:$C$46,0)),"")} -> 30000000 | F13: {=IFERROR(INDEX(#REF!,MATCH($B13,'3_Master_Benchmark'!$C$5:$C$46,0)),"")} | G13: {=IFERROR(INDEX(#REF!,MATCH($B13,'3_Master_Benchmark'!$C$5:$C$46,0)),"")}
A14: {=IFERROR(INDEX('3_Master_Benchmark'!$B$5:$B$46,MATCH($B14,'3_Master_Benchmark'!$C$5:$C$46,0)),"")} -> Midea | B14: MDRS715FGF30ID | C14: {=IFERROR(INDEX('3_Master_Benchmark'!$E$5:$E$46,MATCH($B14,'3_Master_Benchmark'!$C$5:$C$46,0)),"")} -> Side-by-Side | D14: {=IFERROR(INDEX('3_Master_Benchmark'!$F$5:$F$46,MATCH($B14,'3_Master_Benchmark'!$C$5:$C$46,0)),"")} | E14: {=IFERROR(INDEX('3_Master_Benchmark'!$P$5:$P$46,MATCH($B14,'3_Master_Benchmark'!$C$5:$C$46,0)),"")} -> 5000000 | F14: {=IFERROR(INDEX(#REF!,MATCH($B14,'3_Master_Benchmark'!$C$5:$C$46,0)),"")} | G14: {=IFERROR(INDEX(#REF!,MATCH($B14,'3_Master_Benchmark'!$C$5:$C$46,0)),"")}
A16: B. ANGKA KUNCI
A17: Metrik | B17: Nilai
A18: Jumlah SKU dalam benchmark | B18: =COUNTA('3_Master_Benchmark'!$B$5:$B$46) -> 42
A19: Jumlah SKU Haier | B19: =COUNTIFS('3_Master_Benchmark'!$B$5:$B$46,"Haier") -> 9
A20: Rp/Liter rata-rata Haier — Multi-Door 4 Pintu | B20: =IFERROR(AVERAGEIFS(#REF!,'3_Master_Benchmark'!$B$5:$B$46,"Haier",'3_Master_Benchmark'!$E$5:$E$46,"Multi-Door (4 Pintu)"),"")
A21: Rp/Liter rata-rata Sharp — Multi-Door 4 Pintu | B21: =IFERROR(AVERAGEIFS(#REF!,'3_Master_Benchmark'!$B$5:$B$46,"Sharp",'3_Master_Benchmark'!$E$5:$E$46,"Multi-Door (4 Pintu)"),"")
A22: Selisih Haier vs Sharp (Multi-Door 4 Pintu) | B22: =IFERROR(AVERAGEIFS(#REF!,'3_Master_Benchmark'!$B$5:$B$46,"Haier",'3_Master_Benchmark'!$E$5:$E$46,"Multi-Door (4 Pintu)")/AVERAGEIFS(#REF!,'3_Master_Benchmark'!$B$5:$B$46,"Sharp",'3_Master_Benchmark'!$E$5:$E$46,"Multi-Door (4 Pintu)")-1,"")
A23: Rp/Liter SKU volume Haier (Horizon 779RAA) | B23: {=IFERROR(INDEX(#REF!,MATCH("HRF-CTD779RAA(BK)",'3_Master_Benchmark'!$C$5:$C$46,0)),"")}
A24: Rp/Liter SKU acuan Sharp (SJ-IF91PG-GB) | B24: ='6_Referensi'!$B$22
A25: Selisih SKU volume Haier vs acuan Sharp | B25: {=IFERROR(INDEX(#REF!,MATCH("HRF-CTD779RAA(BK)",'3_Master_Benchmark'!$C$5:$C$46,0))/'6_Referensi'!$B$22-1,"")}
A26: Harga tertinggi Haier (Rp) | B26: =IFERROR(MAXIFS('3_Master_Benchmark'!$P$5:$P$46,'3_Master_Benchmark'!$B$5:$B$46,"Haier"),"") -> 0
A27: Harga terendah Haier (Rp) | B27: =IFERROR(MINIFS('3_Master_Benchmark'!$P$5:$P$46,'3_Master_Benchmark'!$B$5:$B$46,"Haier"),"") -> 0
A28: SKU berstatus 'Terverifikasi' | B28: =COUNTIFS(#REF!,"Terverifikasi") -> 0
A29: SKU berstatus 'Belum ada data' | B29: =COUNTIFS(#REF!,"Belum ada data") -> 0
A30: Catatan: Rp/Liter hanya boleh dibandingkan DALAM tipe pintu yang sama. Rata-rata lintas tipe pintu menyesatkan, karena portofolio Haier saat ini seluruhnya multi-door sementara Sharp punya banyak SKU 2 pintu yang murah per liter. Angka rata-rata Haier juga tertarik ke atas oleh halo product 729RITA — karena itu baris 'SKU volume' di atas lebih mewakili posisi harga sebenarnya.
A32: C. TIGA HAL YANG PERLU KEPUTUSAN MANAJEMEN
A33: Temuan | B33: Bukti dari Data | E33: Yang Perlu Diputuskan
A34: 1. Haier TIDAK memasang price premium. | B34: Horizon 779RAA berada di sekitar Rp25,7 rb/liter, LEBIH RENDAH dari flagship Sharp (~Rp29,1 rb/liter) padahal kapasitasnya 61 liter lebih besar. Ini strategi 'more for the same', bukan 'more for more'. | E34: KEPUTUSAN: apakah ini penetration pricing sementara, atau posisi permanen? Jawabannya menentukan target margin 2027.
A35: 2. Entry point Rp8,99 juta berisiko kanibalisasi dengan AQUA. | B35: SKU Space Slim 502L masuk ke pita harga yang secara logika merek seharusnya milik AQUA, dan hanya Rp1 juta di bawah Sharp SJ-IF51. | E35: KEPUTUSAN: pindahkan SKU ini ke AQUA, atau naikkan ke atas Rp10 juta untuk menjaga persepsi premium merek Haier.
A36: 3. Ada lubang portofolio di pita Rp22-35 juta. | B36: Antara Horizon 779RSA (Rp22 jt) dan 729RITA (Rp35 jt) tidak ada SKU. Samsung Bespoke bermain sendirian di rentang ini. | E36: KEPUTUSAN: apakah lubang ini disengaja, dan kapan akan diisi? Setiap bulan kosong = transaksi bernilai tinggi lari ke Samsung.
A38: D. PERINGATAN KUALITAS DATA — sampaikan di awal presentasi
A39: • Harga Haier baru bersumber dari 1 peritel (UFO Elektronika). Belum ada data Hartono, Candi Bantas Pos, maupun Pondok Elektronik.
A40: • Material pintu seluruh SKU Haier masih ASUMSI. Karena material adalah sumbu segmentasi utama tim, ini prioritas verifikasi nomor satu.
A41: • Data AQUA belum ada sama sekali - tanpa ini, analisis kanibalisasi tidak bisa dituntaskan.
A42: • Kapasitas belum dipastikan gross atau nett; perbandingan Rp/Liter lintas merek baru sepenuhnya valid setelah basis diseragamkan.

Sheet 6_Referensi
A1: LEMBAR REFERENSI — Daftar Nilai Baku (jangan diubah tanpa koordinasi)
A3: Tipe Pintu | B3: Band Kapasitas | C3: Material Pintu | D3: Kompresor | E3: Brand | F3: Status Data
A4: 1 Pintu | B4: <150 L | C4: Metal | D4: Inverter | E4: Haier | F4: Terverifikasi
A5: 2 Pintu | B5: 150-200 L | C5: Glass | D5: Non-Inverter | E5: AQUA | F5: Asumsi - perlu cek
A6: Side-by-Side | B6: 200-250 L | E6: Sharp | F6: Belum ada data
A7: Multi-Door (4 Pintu) | B7: 250-300 L | E7: LG
A8: Multi-Door (5 Pintu) | B8: 300-350 L | E8: Samsung
B9: 350-400 L | E9: Midea
B10: 400-450 L | E10: Polytron
B11: 450-500 L | E11: Panasonic
B12: 500-550 L | E12: Electrolux
B13: 550-600 L | E13: Hisense
B14: 600-650 L | E14: Toshiba
B15: 650-700 L | E15: GEA
B16: 700 L ke atas
A20: PARAMETER ACUAN INDEKS HARGA
A21: Model acuan (benchmark leader) | B21: SJ-IF91PG-GB
A22: Rp/Liter model acuan | B22: {=IFERROR(INDEX(#REF!,MATCH($B$21,'3_Master_Benchmark'!$C:$C,0)),"")}
A23: Catatan | B23: Indeks 100 = setara model acuan. >100 = lebih mahal per liter. Ganti kode model di B21 bila acuan berubah.
A26: DAFTAR CHANNEL (sesuai pembagian tim)
A27: Kategori Channel | B27: Nama Channel
A28: Modern | B28: UFO Elektronika
A29: Modern | B29: Hartono Elektronika
A30: Tradisional | B30: Candi Bantas Pos
A31: Tradisional | B31: Pondok Elektronik
A32: Online | B32: E-commerce / Marketplace

Sheet 3_Master_Benchmark
A1: MASTER BENCHMARK SKU — KULKAS INDONESIA
A2: Data ditarik dari UFO Elektronika,
A4: No | B4: Brand | C4: Kode Model | D4: Series | E4: Tipe Pintu | F4: Kapasitas (L) | G4: Material Pintu | H4: Kompresor | I4: Fitur Kunci | J4: Customer Need | K4: MODERN UFO Elektronika (Rp) | L4: MODERN Hartono (Rp) | M4: TRADISIONAL Candi Bantas Pos (Rp) | N4: TRADISIONAL Pondok Elektronik (Rp) | O4: ONLINE E-commerce (Rp) | P4: Harga Rata-rata (Rp) | Q4: Tanggal Update | R4: Sumber / Catatan
A5: 1 | B5: Haier | C5: HRF-CTD729RITA(BK)U1 | D5: Horizon | E5: Multi-Door (4 Pintu) | F5: 650 | G5: Glass | H5: Inverter | I5: ABT Pro; Active Fresh Zone; Magnetic Freshness | J5: Halo product / statement dapur premium | K5: 34999000 | Q5: 04-Agu-2026 | R5: UFO Elektronika, Agu-2026. Material pintu = asumsi.
A6: 2 | B6: Haier | C6: HRF-CTD779RSA(BK)U1 | D6: Horizon | E6: Multi-Door (4 Pintu) | F6: 700 | G6: Glass | H6: Inverter | I6: ABT Pro; Active Fresh Zone; kapasitas jumbo | J6: Keluarga besar 5+ org, stok belanja bulanan | K6: 21999000 | Q6: 04-Agu-2026 | R6: UFO Elektronika, Agu-2026. Material pintu = asumsi.
A7: 3 | B7: Haier | C7: HRF-CTD779RAA(BK) | D7: Horizon | E7: Multi-Door (4 Pintu) | F7: 700 | G7: Glass | H7: Inverter | I7: ABT Pro; kapasitas jumbo | J7: Kapasitas maksimal dengan harga masuk akal | K7: 17999000 | Q7: 04-Agu-2026 | R7: UFO Elektronika, Agu-2026. Material pintu = asumsi.
A8: 4 | B8: Haier | C8: HRF-CMD589RSG(WT)U1 | D8: Space Fit | E8: Multi-Door (5 Pintu) | F8: 512 | G8: Glass | H8: Inverter | I8: 5 pintu; desain hemat ruang | J8: Dapur sempit tapi butuh kompartemen terpisah | K8: 20999000 | Q8: 04-Agu-2026 | R8: UFO Elektronika, Agu-2026. Material pintu = asumsi.
A9: 5 | B9: Haier | C9: HRF-CTD579RSG(WT)U1 | D9: Space Fit | E9: Multi-Door (4 Pintu) | F9: 508 | G9: Glass | H9: Inverter | I9: Desain hemat ruang | J9: Apartemen / rumah tipe menengah | K9: 18999000 | Q9: 04-Agu-2026 | R9: UFO Elektronika, Agu-2026. Material pintu = asumsi.
A10: 6 | B10: Haier | C10: HRF-CTD619RSG(WT)U1 | D10: Space Slim | E10: Multi-Door (4 Pintu) | F10: 550 | G10: Metal | H10: Inverter | I10: Bodi slim, kapasitas besar | J10: Muat di celah dapur sempit | K10: 16999000 | Q10: 04-Agu-2026 | R10: UFO Elektronika, Agu-2026. Material pintu = asumsi.
A11: 7 | B11: Haier | C11: HRF-CTD619RSG(CG)U1 | D11: Space Slim | E11: Multi-Door (4 Pintu) | F11: 550 | G11: Glass | H11: Inverter | I11: Bodi slim; varian Charcoal Grey | J11: Muat di celah dapur sempit | Q11: 04-Agu-2026 | R11: Harga BELUM ditemukan - WAJIB dicek tim.
A12: 8 | B12: Haier | C12: HRF-CTD579RSG(BK)U1 | D12: Space Slim | E12: Multi-Door (4 Pintu) | F12: 500 | G12: Glass | H12: Inverter | I12: Bodi slim | J12: Upgrade pertama dari 2 pintu | K12: 12999000 | Q12: 04-Agu-2026 | R12: UFO Elektronika, Agu-2026. Material pintu = asumsi.
A13: 9 | B13: Haier | C13: HRF-CTD579RAG(BK) | D13: Space Slim | E13: Multi-Door (4 Pintu) | F13: 502 | G13: Glass | H13: Inverter | I13: Bodi slim; entry multi-door | J13: Entry point multi-door termurah Haier | K13: 8999000 | Q13: 04-Agu-2026 | R13: UFO Elektronika, Agu-2026. TITIK KANIBALISASI vs AQUA.
A14: 10 | B14: AQUA | E14: Multi-Door (4 Pintu) | H14: Inverter | I14: [isi fitur] | J14: [isi kebutuhan pelanggan] | P14: =IFERROR(AVERAGE($K14:$O14),"") | Q14: 04-Agu-2026 | R14: CONTOH BARIS - ganti dengan SKU AQUA riil. Kritis untuk cek kanibalisasi.
A15: 11 | B15: AQUA | C15: [isi kode model] | D15: [isi seri] | E15: 2 Pintu | H15: Inverter | I15: [isi fitur] | J15: [isi kebutuhan pelanggan] | P15: =IFERROR(AVERAGE($K15:$O15),"") | Q15: 04-Agu-2026 | R15: CONTOH BARIS - ganti dengan SKU AQUA riil.
A16: 12 | B16: Sharp | C16: SJ-IF91PG-GB | E16: Multi-Door (4 Pintu) | F16: 639 | G16: Glass | H16: Inverter | I16: Plasmacluster Ion; J-Tech Inverter; Full Tempered Glass | J16: Keluarga besar, cari merek paling dipercaya | O16: 18599000 | P16: =IFERROR(AVERAGE($K16:$O16),"") -> 18599000 | Q16: 04-Agu-2026 | R16: Media/ritel, Mei-2026. MODEL ACUAN BENCHMARK.
A17: 13 | B17: Sharp | C17: SJ-IF51P-GCG | E17: Multi-Door (4 Pintu) | F17: 472 | G17: Glass | H17: Inverter | I17: J-Tech Inverter; humidity control; kaca motif | J17: Tampilan premium tanpa harga tertinggi | O17: 10399000 | P17: =IFERROR(AVERAGE($K17:$O17),"") -> 10399000 | Q17: 04-Agu-2026 | R17: Media/ritel, Mei-2026.
A18: 14 | B18: Sharp | C18: SJ-IF51PG-BK | E18: Multi-Door (4 Pintu) | F18: 472 | G18: Glass | H18: Inverter | I18: Twist Ice Maker; 4 boks freezer | J18: Multi-door entry dengan brand kuat | O18: 9569000 | P18: =IFERROR(AVERAGE($K18:$O18),"") -> 9569000 | Q18: 04-Agu-2026 | R18: Mitra10, 2026.
A19: 15 | B19: Sharp | C19: SJ-IF90PM-DS | E19: Side-by-Side | G19: Glass | H19: Inverter | I19: Side-by-side 4 pintu | J19: Statement dapur + kapasitas | O19: 15456122 | P19: =IFERROR(AVERAGE($K19:$O19),"") -> 15456122 | Q19: 04-Agu-2026 | R19: Mitra10, 2026. Kapasitas & material perlu dicek.
A20: 16 | B20: Sharp | C20: SJ-IG963PG-BK | E20: 2 Pintu | F20: 656 | G20: Glass | H20: Inverter | I20: Plasmacluster; kaca hitam | J20: Kapasitas besar tanpa pindah ke multi-door | O20: 11090817 | P20: =IFERROR(AVERAGE($K20:$O20),"") -> 11090817 | Q20: 04-Agu-2026 | R20: Mitra10, 2026.
A21: 17 | B21: Sharp | C21: SJ-IG863PG-BK | E21: 2 Pintu | F21: 613 | G21: Glass | H21: Inverter | I21: Plasmacluster; kaca hitam | J21: Kapasitas besar, budget menengah | O21: 10815306 | P21: =IFERROR(AVERAGE($K21:$O21),"") -> 10815306 | Q21: 04-Agu-2026 | R21: Mitra10, 2026.
A22: 18 | B22: Sharp | C22: SJ-IG962PM-SL | E22: 2 Pintu | F22: 656 | G22: Metal | H22: Inverter | I22: Plasmacluster; finish metal | J22: Kapasitas besar, harga lebih rendah dari glass | O22: 9998980 | P22: =IFERROR(AVERAGE($K22:$O22),"") -> 9998980 | Q22: 04-Agu-2026 | R22: Mitra10, 2026. Selisih Glass vs Metal terlihat di sini.
A23: 19 | B23: Sharp | C23: SJ-456GI-MK | E23: 2 Pintu | G23: Glass | H23: Inverter | I23: Inverter; No Frost | J23: Keluarga inti, kebutuhan standar | O23: 5729000 | P23: =IFERROR(AVERAGE($K23:$O23),"") -> 5729000 | Q23: 04-Agu-2026 | R23: Mitra10, 2026. Kapasitas perlu dicek.
A24: 20 | B24: Sharp | C24: SJ-326XI-MK | E24: 2 Pintu | G24: Glass | H24: Inverter | I24: Inverter | J24: Keluarga muda | O24: 4866326 | P24: =IFERROR(AVERAGE($K24:$O24),"") -> 4866326 | Q24: 04-Agu-2026 | R24: Mitra10, 2026. Kapasitas perlu dicek.
A25: 21 | B25: Sharp | C25: SJ-317MG | E25: 2 Pintu | F25: 256 | G25: Metal | H25: Non-Inverter | I25: Non-inverter, entry | J25: Entry level, sensitif harga | O25: 3171430 | P25: =IFERROR(AVERAGE($K25:$O25),"") -> 3171430 | Q25: 04-Agu-2026 | R25: Mitra10, 2026.
A26: 22 | B26: LG | C26: GC-X257CSEW | D26: InstaView | E26: Side-by-Side | F26: 674 | G26: Metal | H26: Inverter | I26: InstaView Door-in-Door; UVnano; Smart Control | J26: Premium tech + gaya hidup smart home | P26: =IFERROR(AVERAGE($K26:$O26),"") | Q26: 04-Agu-2026 | R26: Blibli listing, harga belum terekstrak. WAJIB dicek.
A27: 23 | B27: LG | C27: GC-L257CQEL/BL | E27: Side-by-Side | F27: 674 | G27: Metal | H27: Inverter | I27: Smart Inverter Compressor | J27: Kapasitas besar merek Korea | O27: 18233673 | P27: =IFERROR(AVERAGE($K27:$O27),"") -> 18233673 | Q27: 04-Agu-2026 | R27: Mitra10, 2026. Material perlu dicek.
A28: 24 | B28: LG | C28: GC-B257SQYL | E28: Side-by-Side | F28: 694 | G28: Metal | H28: Inverter | I28: Smart Inverter Compressor; pintu UltraSleek | J28: Kapasitas maksimal, harga agresif | O28: 12029000 | P28: =IFERROR(AVERAGE($K28:$O28),"") -> 12029000 | Q28: 04-Agu-2026 | R28: Blibli, 2026. Pesaing harga langsung Horizon 779RAA.
A29: 25 | B29: LG | C29: GC-L22FFLQB | E29: Multi-Door (4 Pintu) | F29: 570 | G29: Metal | H29: Inverter | I29: Smart Inverter Compressor | J29: Multi-door merek Korea | P29: =IFERROR(AVERAGE($K29:$O29),"") | Q29: 04-Agu-2026 | R29: Blibli listing, harga belum terekstrak.
A30: 26 | B30: LG | C30: GN-B262PQSF | E30: 2 Pintu | F30: 287 | G30: Metal | H30: Inverter | I30: Inverter; No Frost; rak kaca tempered | J30: Keluarga inti | O30: 5329000 | P30: =IFERROR(AVERAGE($K30:$O30),"") -> 5329000 | Q30: 04-Agu-2026 | R30: Blibli, 2026.
A31: 27 | B31: LG | C31: GN-B212PQNF | E31: 2 Pintu | F31: 235 | G31: Metal | H31: Inverter | I31: Multi Air Flow; Fresh O Zone; Inverter | J31: Keluarga muda / pasangan baru | O31: 4419000 | P31: =IFERROR(AVERAGE($K31:$O31),"") -> 4419000 | Q31: 04-Agu-2026 | R31: Blibli, 2026.
A32: 28 | B32: Samsung | C32: RS90F65DNFSE | D32: Bespoke AI | E32: Side-by-Side | F32: 641 | G32: Metal | H32: Inverter | I32: AI Home 9"/Family Hub 21,5"; SpaceMax; SmartThings | J32: Early adopter tech, smart home | O32: 30000000 | P32: =IFERROR(AVERAGE($K32:$O32),"") -> 30000000 | Q32: 04-Agu-2026 | R32: Media, Apr-2026. Harga ESTIMASI, wajib dicek ritel.
A33: 29 | B33: Samsung | C33: RF65DB90B012SE | D33: Bespoke Multidoor | E33: Multi-Door (4 Pintu) | F33: 681 | G33: Glass | H33: Inverter | I33: Triple Cooling; panel warna kustom | J33: Personalisasi desain dapur | P33: =IFERROR(AVERAGE($K33:$O33),"") | Q33: 04-Agu-2026 | R33: Blibli listing, harga belum terekstrak.
A34: 30 | B34: Samsung | C34: RT38CG6420B1SE | D34: Ungkep Compartment | E34: 2 Pintu | F34: 393 | G34: Metal | H34: Inverter | I34: Ungkep Compartment (fitur lokal) | J34: Kebiasaan masak Indonesia | O34: 8294898 | P34: =IFERROR(AVERAGE($K34:$O34),"") -> 8294898 | Q34: 04-Agu-2026 | R34: Mitra10, 2026.
A35: 31 | B35: Samsung | C35: RT38CB66408J | D35: Bespoke 2 Pintu | E35: 2 Pintu | F35: 393 | G35: Metal | H35: Inverter | I35: Bespoke panel warna | J35: Estetika dapur, budget menengah | O35: 8866326 | P35: =IFERROR(AVERAGE($K35:$O35),"") -> 8866326 | Q35: 04-Agu-2026 | R35: Mitra10, 2026.
A36: 32 | B36: Samsung | C36: RT35CG5440S9SE | D36: Ungkep Compartment | E36: 2 Pintu | F36: 348 | G36: Metal | H36: Inverter | I36: Ungkep Compartment | J36: Kebiasaan masak Indonesia | O36: 7570408 | P36: =IFERROR(AVERAGE($K36:$O36),"") -> 7570408 | Q36: 04-Agu-2026 | R36: Mitra10, 2026.
A37: 33 | B37: Midea | C37: MDRS715FGF30ID | E37: Side-by-Side | G37: Metal | H37: Inverter | I37: Platinum Fresh; Multi Air Flow; ruang +30cm | J37: Kapasitas besar, budget terbatas | O37: 5000000 | P37: =IFERROR(AVERAGE($K37:$O37),"") -> 5000000 | Q37: 04-Agu-2026 | R37: Rilis pers Feb-2026 'mulai Rp5 jutaan'. Kapasitas & harga riil WAJIB dicek.
A38: 34 | B38: Midea | C38: Everest | E38: 2 Pintu | F38: 473 | G38: Metal | H38: Inverter | I38: Kapasitas terbesar di kelasnya | J38: Kapasitas besar harga entry | O38: 4500000 | P38: =IFERROR(AVERAGE($K38:$O38),"") -> 4500000 | Q38: 04-Agu-2026 | R38: Rilis pers Jan-2025 'mulai Rp4,5 jutaan'. Perlu cek harga terkini.
A39: 35 | B39: Electrolux | C39: EQE4960A-B | D39: UltimateTaste | E39: Multi-Door (4 Pintu) | F39: 537 | G39: Glass | H39: Inverter | I39: TasteLock; Dual Crisper; EvenTemp | J39: Positioning Eropa, food preservation | P39: =IFERROR(AVERAGE($K39:$O39),"") | Q39: 04-Agu-2026 | R39: Blibli listing, harga belum terekstrak.
A40: 36 | B40: Electrolux | C40: EQE5600A-S | D40: UltimateTaste 700 | E40: Multi-Door (4 Pintu) | F40: 562 | G40: Metal | H40: Inverter | I40: Kompresor inverter | J40: Positioning Eropa | P40: =IFERROR(AVERAGE($K40:$O40),"") | Q40: 04-Agu-2026 | R40: Blibli listing, harga belum terekstrak.
A41: 37 | B41: Electrolux | C41: EQE4905A-B | D41: UltimateTaste 600 | E41: Multi-Door (4 Pintu) | F41: 496 | G41: Glass | H41: Inverter | I41: No Frost; QuickFreeze; desain kaca | J41: Estetika + preservation | P41: =IFERROR(AVERAGE($K41:$O41),"") | Q41: 04-Agu-2026 | R41: UFO listing, harga belum terekstrak.
...

Sheet 4_Matriks_Segmen
A1: MATRIKS SEGMENTASI — PETA PORTOFOLIO & POSISI HARGA
A2: Semua angka terhitung otomatis dari 3_Master_Benchmark. Sel kosong = tidak ada SKU di segmen tersebut (ini adalah GAP, bukan error).
A4: GRID 1 — CAKUPAN PORTOFOLIO per TIPE PINTU (jumlah SKU)
A5: Baca: di mana kita punya SKU, di mana kompetitor punya dan kita tidak. Angka 0 di kolom Haier/AQUA = white space.
A6: Tipe Pintu | B6: Haier | C6: AQUA | D6: Sharp | E6: LG | F6: Samsung | G6: Midea | H6: Polytron | I6: Electrolux
A7: 1 Pintu | B7: =COUNTIFS('3_Master_Benchmark'!$E$5:$E$46,$A7,'3_Master_Benchmark'!$B$5:$B$46,B$6) -> 0 | C7: =COUNTIFS('3_Master_Benchmark'!$E$5:$E$46,$A7,'3_Master_Benchmark'!$B$5:$B$46,C$6) -> 0 | D7: =COUNTIFS('3_Master_Benchmark'!$E$5:$E$46,$A7,'3_Master_Benchmark'!$B$5:$B$46,D$6) -> 0 | E7: =COUNTIFS('3_Master_Benchmark'!$E$5:$E$46,$A7,'3_Master_Benchmark'!$B$5:$B$46,E$6) -> 0 | F7: =COUNTIFS('3_Master_Benchmark'!$E$5:$E$46,$A7,'3_Master_Benchmark'!$B$5:$B$46,F$6) -> 0 | G7: =COUNTIFS('3_Master_Benchmark'!$E$5:$E$46,$A7,'3_Master_Benchmark'!$B$5:$B$46,G$6) -> 0 | H7: =COUNTIFS('3_Master_Benchmark'!$E$5:$E$46,$A7,'3_Master_Benchmark'!$B$5:$B$46,H$6) -> 0 | I7: =COUNTIFS('3_Master_Benchmark'!$E$5:$E$46,$A7,'3_Master_Benchmark'!$B$5:$B$46,I$6) -> 0
A8: 2 Pintu | B8: =COUNTIFS('3_Master_Benchmark'!$E$5:$E$46,$A8,'3_Master_Benchmark'!$B$5:$B$46,B$6) -> 0 | C8: =COUNTIFS('3_Master_Benchmark'!$E$5:$E$46,$A8,'3_Master_Benchmark'!$B$5:$B$46,C$6) -> 1 | D8: =COUNTIFS('3_Master_Benchmark'!$E$5:$E$46,$A8,'3_Master_Benchmark'!$B$5:$B$46,D$6) -> 6 | E8: =COUNTIFS('3_Master_Benchmark'!$E$5:$E$46,$A8,'3_Master_Benchmark'!$B$5:$B$46,E$6) -> 2 | F8: =COUNTIFS('3_Master_Benchmark'!$E$5:$E$46,$A8,'3_Master_Benchmark'!$B$5:$B$46,F$6) -> 3 | G8: =COUNTIFS('3_Master_Benchmark'!$E$5:$E$46,$A8,'3_Master_Benchmark'!$B$5:$B$46,G$6) -> 1 | H8: =COUNTIFS('3_Master_Benchmark'!$E$5:$E$46,$A8,'3_Master_Benchmark'!$B$5:$B$46,H$6) -> 1 | I8: =COUNTIFS('3_Master_Benchmark'!$E$5:$E$46,$A8,'3_Master_Benchmark'!$B$5:$B$46,I$6) -> 0
A9: Side-by-Side | B9: =COUNTIFS('3_Master_Benchmark'!$E$5:$E$46,$A9,'3_Master_Benchmark'!$B$5:$B$46,B$6) -> 0 | C9: =COUNTIFS('3_Master_Benchmark'!$E$5:$E$46,$A9,'3_Master_Benchmark'!$B$5:$B$46,C$6) -> 0 | D9: =COUNTIFS('3_Master_Benchmark'!$E$5:$E$46,$A9,'3_Master_Benchmark'!$B$5:$B$46,D$6) -> 1 | E9: =COUNTIFS('3_Master_Benchmark'!$E$5:$E$46,$A9,'3_Master_Benchmark'!$B$5:$B$46,E$6) -> 3 | F9: =COUNTIFS('3_Master_Benchmark'!$E$5:$E$46,$A9,'3_Master_Benchmark'!$B$5:$B$46,F$6) -> 1 | G9: =COUNTIFS('3_Master_Benchmark'!$E$5:$E$46,$A9,'3_Master_Benchmark'!$B$5:$B$46,G$6) -> 1 | H9: =COUNTIFS('3_Master_Benchmark'!$E$5:$E$46,$A9,'3_Master_Benchmark'!$B$5:$B$46,H$6) -> 0 | I9: =COUNTIFS('3_Master_Benchmark'!$E$5:$E$46,$A9,'3_Master_Benchmark'!$B$5:$B$46,I$6) -> 0
A10: Multi-Door (4 Pintu) | B10: =COUNTIFS('3_Master_Benchmark'!$E$5:$E$46,$A10,'3_Master_Benchmark'!$B$5:$B$46,B$6) -> 8 | C10: =COUNTIFS('3_Master_Benchmark'!$E$5:$E$46,$A10,'3_Master_Benchmark'!$B$5:$B$46,C$6) -> 1 | D10: =COUNTIFS('3_Master_Benchmark'!$E$5:$E$46,$A10,'3_Master_Benchmark'!$B$5:$B$46,D$6) -> 3 | E10: =COUNTIFS('3_Master_Benchmark'!$E$5:$E$46,$A10,'3_Master_Benchmark'!$B$5:$B$46,E$6) -> 1 | F10: =COUNTIFS('3_Master_Benchmark'!$E$5:$E$46,$A10,'3_Master_Benchmark'!$B$5:$B$46,F$6) -> 1 | G10: =COUNTIFS('3_Master_Benchmark'!$E$5:$E$46,$A10,'3_Master_Benchmark'!$B$5:$B$46,G$6) -> 0 | H10: =COUNTIFS('3_Master_Benchmark'!$E$5:$E$46,$A10,'3_Master_Benchmark'!$B$5:$B$46,H$6) -> 0 | I10: =COUNTIFS('3_Master_Benchmark'!$E$5:$E$46,$A10,'3_Master_Benchmark'!$B$5:$B$46,I$6) -> 3
A11: Multi-Door (5 Pintu) | B11: =COUNTIFS('3_Master_Benchmark'!$E$5:$E$46,$A11,'3_Master_Benchmark'!$B$5:$B$46,B$6) -> 1 | C11: =COUNTIFS('3_Master_Benchmark'!$E$5:$E$46,$A11,'3_Master_Benchmark'!$B$5:$B$46,C$6) -> 0 | D11: =COUNTIFS('3_Master_Benchmark'!$E$5:$E$46,$A11,'3_Master_Benchmark'!$B$5:$B$46,D$6) -> 0 | E11: =COUNTIFS('3_Master_Benchmark'!$E$5:$E$46,$A11,'3_Master_Benchmark'!$B$5:$B$46,E$6) -> 0 | F11: =COUNTIFS('3_Master_Benchmark'!$E$5:$E$46,$A11,'3_Master_Benchmark'!$B$5:$B$46,F$6) -> 0 | G11: =COUNTIFS('3_Master_Benchmark'!$E$5:$E$46,$A11,'3_Master_Benchmark'!$B$5:$B$46,G$6) -> 0 | H11: =COUNTIFS('3_Master_Benchmark'!$E$5:$E$46,$A11,'3_Master_Benchmark'!$B$5:$B$46,H$6) -> 0 | I11: =COUNTIFS('3_Master_Benchmark'!$E$5:$E$46,$A11,'3_Master_Benchmark'!$B$5:$B$46,I$6) -> 0
A14: GRID 2 — CAKUPAN PORTOFOLIO per BAND KAPASITAS (jumlah SKU)
A15: Baca: apakah tangga kapasitas kita rapat atau berlubang. Lubang = konsumen dengan budget itu diarahkan ke merek lain.
A16: Band Kapasitas | B16: Haier | C16: AQUA | D16: Sharp | E16: LG | F16: Samsung | G16: Midea | H16: Polytron | I16: Electrolux
A17: <150 L | B17: =COUNTIFS(#REF!,$A17,'3_Master_Benchmark'!$B$5:$B$46,B$16) -> #VALUE! | C17: =COUNTIFS(#REF!,$A17,'3_Master_Benchmark'!$B$5:$B$46,C$16) -> #VALUE! | D17: =COUNTIFS(#REF!,$A17,'3_Master_Benchmark'!$B$5:$B$46,D$16) -> #VALUE! | E17: =COUNTIFS(#REF!,$A17,'3_Master_Benchmark'!$B$5:$B$46,E$16) -> #VALUE! | F17: =COUNTIFS(#REF!,$A17,'3_Master_Benchmark'!$B$5:$B$46,F$16) -> #VALUE! | G17: =COUNTIFS(#REF!,$A17,'3_Master_Benchmark'!$B$5:$B$46,G$16) -> #VALUE! | H17: =COUNTIFS(#REF!,$A17,'3_Master_Benchmark'!$B$5:$B$46,H$16) -> #VALUE! | I17: =COUNTIFS(#REF!,$A17,'3_Master_Benchmark'!$B$5:$B$46,I$16) -> #VALUE!
A18: 150-200 L | B18: =COUNTIFS(#REF!,$A18,'3_Master_Benchmark'!$B$5:$B$46,B$16) -> #VALUE! | C18: =COUNTIFS(#REF!,$A18,'3_Master_Benchmark'!$B$5:$B$46,C$16) -> #VALUE! | D18: =COUNTIFS(#REF!,$A18,'3_Master_Benchmark'!$B$5:$B$46,D$16) -> #VALUE! | E18: =COUNTIFS(#REF!,$A18,'3_Master_Benchmark'!$B$5:$B$46,E$16) -> #VALUE! | F18: =COUNTIFS(#REF!,$A18,'3_Master_Benchmark'!$B$5:$B$46,F$16) -> #VALUE! | G18: =COUNTIFS(#REF!,$A18,'3_Master_Benchmark'!$B$5:$B$46,G$16) -> #VALUE! | H18: =COUNTIFS(#REF!,$A18,'3_Master_Benchmark'!$B$5:$B$46,H$16) -> #VALUE! | I18: =COUNTIFS(#REF!,$A18,'3_Master_Benchmark'!$B$5:$B$46,I$16) -> #VALUE!
A19: 200-250 L | B19: =COUNTIFS(#REF!,$A19,'3_Master_Benchmark'!$B$5:$B$46,B$16) -> #VALUE! | C19: =COUNTIFS(#REF!,$A19,'3_Master_Benchmark'!$B$5:$B$46,C$16) -> #VALUE! | D19: =COUNTIFS(#REF!,$A19,'3_Master_Benchmark'!$B$5:$B$46,D$16) -> #VALUE! | E19: =COUNTIFS(#REF!,$A19,'3_Master_Benchmark'!$B$5:$B$46,E$16) -> #VALUE! | F19: =COUNTIFS(#REF!,$A19,'3_Master_Benchmark'!$B$5:$B$46,F$16) -> #VALUE! | G19: =COUNTIFS(#REF!,$A19,'3_Master_Benchmark'!$B$5:$B$46,G$16) -> #VALUE! | H19: =COUNTIFS(#REF!,$A19,'3_Master_Benchmark'!$B$5:$B$46,H$16) -> #VALUE! | I19: =COUNTIFS(#REF!,$A19,'3_Master_Benchmark'!$B$5:$B$46,I$16) -> #VALUE!
A20: 250-300 L | B20: =COUNTIFS(#REF!,$A20,'3_Master_Benchmark'!$B$5:$B$46,B$16) -> #VALUE! | C20: =COUNTIFS(#REF!,$A20,'3_Master_Benchmark'!$B$5:$B$46,C$16) -> #VALUE! | D20: =COUNTIFS(#REF!,$A20,'3_Master_Benchmark'!$B$5:$B$46,D$16) -> #VALUE! | E20: =COUNTIFS(#REF!,$A20,'3_Master_Benchmark'!$B$5:$B$46,E$16) -> #VALUE! | F20: =COUNTIFS(#REF!,$A20,'3_Master_Benchmark'!$B$5:$B$46,F$16) -> #VALUE! | G20: =COUNTIFS(#REF!,$A20,'3_Master_Benchmark'!$B$5:$B$46,G$16) -> #VALUE! | H20: =COUNTIFS(#REF!,$A20,'3_Master_Benchmark'!$B$5:$B$46,H$16) -> #VALUE! | I20: =COUNTIFS(#REF!,$A20,'3_Master_Benchmark'!$B$5:$B$46,I$16) -> #VALUE!
A21: 300-350 L | B21: =COUNTIFS(#REF!,$A21,'3_Master_Benchmark'!$B$5:$B$46,B$16) -> #VALUE! | C21: =COUNTIFS(#REF!,$A21,'3_Master_Benchmark'!$B$5:$B$46,C$16) -> #VALUE! | D21: =COUNTIFS(#REF!,$A21,'3_Master_Benchmark'!$B$5:$B$46,D$16) -> #VALUE! | E21: =COUNTIFS(#REF!,$A21,'3_Master_Benchmark'!$B$5:$B$46,E$16) -> #VALUE! | F21: =COUNTIFS(#REF!,$A21,'3_Master_Benchmark'!$B$5:$B$46,F$16) -> #VALUE! | G21: =COUNTIFS(#REF!,$A21,'3_Master_Benchmark'!$B$5:$B$46,G$16) -> #VALUE! | H21: =COUNTIFS(#REF!,$A21,'3_Master_Benchmark'!$B$5:$B$46,H$16) -> #VALUE! | I21: =COUNTIFS(#REF!,$A21,'3_Master_Benchmark'!$B$5:$B$46,I$16) -> #VALUE!
A22: 350-400 L | B22: =COUNTIFS(#REF!,$A22,'3_Master_Benchmark'!$B$5:$B$46,B$16) -> #VALUE! | C22: =COUNTIFS(#REF!,$A22,'3_Master_Benchmark'!$B$5:$B$46,C$16) -> #VALUE! | D22: =COUNTIFS(#REF!,$A22,'3_Master_Benchmark'!$B$5:$B$46,D$16) -> #VALUE! | E22: =COUNTIFS(#REF!,$A22,'3_Master_Benchmark'!$B$5:$B$46,E$16) -> #VALUE! | F22: =COUNTIFS(#REF!,$A22,'3_Master_Benchmark'!$B$5:$B$46,F$16) -> #VALUE! | G22: =COUNTIFS(#REF!,$A22,'3_Master_Benchmark'!$B$5:$B$46,G$16) -> #VALUE! | H22: =COUNTIFS(#REF!,$A22,'3_Master_Benchmark'!$B$5:$B$46,H$16) -> #VALUE! | I22: =COUNTIFS(#REF!,$A22,'3_Master_Benchmark'!$B$5:$B$46,I$16) -> #VALUE!
A23: 400-450 L | B23: =COUNTIFS(#REF!,$A23,'3_Master_Benchmark'!$B$5:$B$46,B$16) -> #VALUE! | C23: =COUNTIFS(#REF!,$A23,'3_Master_Benchmark'!$B$5:$B$46,C$16) -> #VALUE! | D23: =COUNTIFS(#REF!,$A23,'3_Master_Benchmark'!$B$5:$B$46,D$16) -> #VALUE! | E23: =COUNTIFS(#REF!,$A23,'3_Master_Benchmark'!$B$5:$B$46,E$16) -> #VALUE! | F23: =COUNTIFS(#REF!,$A23,'3_Master_Benchmark'!$B$5:$B$46,F$16) -> #VALUE! | G23: =COUNTIFS(#REF!,$A23,'3_Master_Benchmark'!$B$5:$B$46,G$16) -> #VALUE! | H23: =COUNTIFS(#REF!,$A23,'3_Master_Benchmark'!$B$5:$B$46,H$16) -> #VALUE! | I23: =COUNTIFS(#REF!,$A23,'3_Master_Benchmark'!$B$5:$B$46,I$16) -> #VALUE!
A24: 450-500 L | B24: =COUNTIFS(#REF!,$A24,'3_Master_Benchmark'!$B$5:$B$46,B$16) -> #VALUE! | C24: =COUNTIFS(#REF!,$A24,'3_Master_Benchmark'!$B$5:$B$46,C$16) -> #VALUE! | D24: =COUNTIFS(#REF!,$A24,'3_Master_Benchmark'!$B$5:$B$46,D$16) -> #VALUE! | E24: =COUNTIFS(#REF!,$A24,'3_Master_Benchmark'!$B$5:$B$46,E$16) -> #VALUE! | F24: =COUNTIFS(#REF!,$A24,'3_Master_Benchmark'!$B$5:$B$46,F$16) -> #VALUE! | G24: =COUNTIFS(#REF!,$A24,'3_Master_Benchmark'!$B$5:$B$46,G$16) -> #VALUE! | H24: =COUNTIFS(#REF!,$A24,'3_Master_Benchmark'!$B$5:$B$46,H$16) -> #VALUE! | I24: =COUNTIFS(#REF!,$A24,'3_Master_Benchmark'!$B$5:$B$46,I$16) -> #VALUE!
A25: 500-550 L | B25: =COUNTIFS(#REF!,$A25,'3_Master_Benchmark'!$B$5:$B$46,B$16) -> #VALUE! | C25: =COUNTIFS(#REF!,$A25,'3_Master_Benchmark'!$B$5:$B$46,C$16) -> #VALUE! | D25: =COUNTIFS(#REF!,$A25,'3_Master_Benchmark'!$B$5:$B$46,D$16) -> #VALUE! | E25: =COUNTIFS(#REF!,$A25,'3_Master_Benchmark'!$B$5:$B$46,E$16) -> #VALUE! | F25: =COUNTIFS(#REF!,$A25,'3_Master_Benchmark'!$B$5:$B$46,F$16) -> #VALUE! | G25: =COUNTIFS(#REF!,$A25,'3_Master_Benchmark'!$B$5:$B$46,G$16) -> #VALUE! | H25: =COUNTIFS(#REF!,$A25,'3_Master_Benchmark'!$B$5:$B$46,H$16) -> #VALUE! | I25: =COUNTIFS(#REF!,$A25,'3_Master_Benchmark'!$B$5:$B$46,I$16) -> #VALUE!
A26: 550-600 L | B26: =COUNTIFS(#REF!,$A26,'3_Master_Benchmark'!$B$5:$B$46,B$16) -> #VALUE! | C26: =COUNTIFS(#REF!,$A26,'3_Master_Benchmark'!$B$5:$B$46,C$16) -> #VALUE! | D26: =COUNTIFS(#REF!,$A26,'3_Master_Benchmark'!$B$5:$B$46,D$16) -> #VALUE! | E26: =COUNTIFS(#REF!,$A26,'3_Master_Benchmark'!$B$5:$B$46,E$16) -> #VALUE! | F26: =COUNTIFS(#REF!,$A26,'3_Master_Benchmark'!$B$5:$B$46,F$16) -> #VALUE! | G26: =COUNTIFS(#REF!,$A26,'3_Master_Benchmark'!$B$5:$B$46,G$16) -> #VALUE! | H26: =COUNTIFS(#REF!,$A26,'3_Master_Benchmark'!$B$5:$B$46,H$16) -> #VALUE! | I26: =COUNTIFS(#REF!,$A26,'3_Master_Benchmark'!$B$5:$B$46,I$16) -> #VALUE!
A27: 600-650 L | B27: =COUNTIFS(#REF!,$A27,'3_Master_Benchmark'!$B$5:$B$46,B$16) -> #VALUE! | C27: =COUNTIFS(#REF!,$A27,'3_Master_Benchmark'!$B$5:$B$46,C$16) -> #VALUE! | D27: =COUNTIFS(#REF!,$A27,'3_Master_Benchmark'!$B$5:$B$46,D$16) -> #VALUE! | E27: =COUNTIFS(#REF!,$A27,'3_Master_Benchmark'!$B$5:$B$46,E$16) -> #VALUE! | F27: =COUNTIFS(#REF!,$A27,'3_Master_Benchmark'!$B$5:$B$46,F$16) -> #VALUE! | G27: =COUNTIFS(#REF!,$A27,'3_Master_Benchmark'!$B$5:$B$46,G$16) -> #VALUE! | H27: =COUNTIFS(#REF!,$A27,'3_Master_Benchmark'!$B$5:$B$46,H$16) -> #VALUE! | I27: =COUNTIFS(#REF!,$A27,'3_Master_Benchmark'!$B$5:$B$46,I$16) -> #VALUE!
A28: 650-700 L | B28: =COUNTIFS(#REF!,$A28,'3_Master_Benchmark'!$B$5:$B$46,B$16) -> #VALUE! | C28: =COUNTIFS(#REF!,$A28,'3_Master_Benchmark'!$B$5:$B$46,C$16) -> #VALUE! | D28: =COUNTIFS(#REF!,$A28,'3_Master_Benchmark'!$B$5:$B$46,D$16) -> #VALUE! | E28: =COUNTIFS(#REF!,$A28,'3_Master_Benchmark'!$B$5:$B$46,E$16) -> #VALUE! | F28: =COUNTIFS(#REF!,$A28,'3_Master_Benchmark'!$B$5:$B$46,F$16) -> #VALUE! | G28: =COUNTIFS(#REF!,$A28,'3_Master_Benchmark'!$B$5:$B$46,G$16) -> #VALUE! | H28: =COUNTIFS(#REF!,$A28,'3_Master_Benchmark'!$B$5:$B$46,H$16) -> #VALUE! | I28: =COUNTIFS(#REF!,$A28,'3_Master_Benchmark'!$B$5:$B$46,I$16) -> #VALUE!
A29: 700 L ke atas | B29: =COUNTIFS(#REF!,$A29,'3_Master_Benchmark'!$B$5:$B$46,B$16) -> #VALUE! | C29: =COUNTIFS(#REF!,$A29,'3_Master_Benchmark'!$B$5:$B$46,C$16) -> #VALUE! | D29: =COUNTIFS(#REF!,$A29,'3_Master_Benchmark'!$B$5:$B$46,D$16) -> #VALUE! | E29: =COUNTIFS(#REF!,$A29,'3_Master_Benchmark'!$B$5:$B$46,E$16) -> #VALUE! | F29: =COUNTIFS(#REF!,$A29,'3_Master_Benchmark'!$B$5:$B$46,F$16) -> #VALUE! | G29: =COUNTIFS(#REF!,$A29,'3_Master_Benchmark'!$B$5:$B$46,G$16) -> #VALUE! | H29: =COUNTIFS(#REF!,$A29,'3_Master_Benchmark'!$B$5:$B$46,H$16) -> #VALUE! | I29: =COUNTIFS(#REF!,$A29,'3_Master_Benchmark'!$B$5:$B$46,I$16) -> #VALUE!
A32: GRID 3 — HARGA RATA-RATA per BAND KAPASITAS (Rp)
A33: Baca: pada kapasitas yang sama, kita lebih mahal atau lebih murah dari kompetitor.
A34: Band Kapasitas | B34: Haier | C34: AQUA | D34: Sharp | E34: LG | F34: Samsung | G34: Midea | H34: Polytron | I34: Electrolux
A35: <150 L | B35: =IFERROR(AVERAGEIFS('3_Master_Benchmark'!$P$5:$P$46,#REF!,$A35,'3_Master_Benchmark'!$B$5:$B$46,B$34),"") | C35: =IFERROR(AVERAGEIFS('3_Master_Benchmark'!$P$5:$P$46,#REF!,$A35,'3_Master_Benchmark'!$B$5:$B$46,C$34),"") | D35: =IFERROR(AVERAGEIFS('3_Master_Benchmark'!$P$5:$P$46,#REF!,$A35,'3_Master_Benchmark'!$B$5:$B$46,D$34),"") | E35: =IFERROR(AVERAGEIFS('3_Master_Benchmark'!$P$5:$P$46,#REF!,$A35,'3_Master_Benchmark'!$B$5:$B$46,E$34),"") | F35: =IFERROR(AVERAGEIFS('3_Master_Benchmark'!$P$5:$P$46,#REF!,$A35,'3_Master_Benchmark'!$B$5:$B$46,F$34),"") | G35: =IFERROR(AVERAGEIFS('3_Master_Benchmark'!$P$5:$P$46,#REF!,$A35,'3_Master_Benchmark'!$B$5:$B$46,G$34),"") | H35: =IFERROR(AVERAGEIFS('3_Master_Benchmark'!$P$5:$P$46,#REF!,$A35,'3_Master_Benchmark'!$B$5:$B$46,H$34),"") | I35: =IFERROR(AVERAGEIFS('3_Master_Benchmark'!$P$5:$P$46,#REF!,$A35,'3_Master_Benchmark'!$B$5:$B$46,I$34),"")
A36: 150-200 L | B36: =IFERROR(AVERAGEIFS('3_Master_Benchmark'!$P$5:$P$46,#REF!,$A36,'3_Master_Benchmark'!$B$5:$B$46,B$34),"") | C36: =IFERROR(AVERAGEIFS('3_Master_Benchmark'!$P$5:$P$46,#REF!,$A36,'3_Master_Benchmark'!$B$5:$B$46,C$34),"") | D36: =IFERROR(AVERAGEIFS('3_Master_Benchmark'!$P$5:$P$46,#REF!,$A36,'3_Master_Benchmark'!$B$5:$B$46,D$34),"") | E36: =IFERROR(AVERAGEIFS('3_Master_Benchmark'!$P$5:$P$46,#REF!,$A36,'3_Master_Benchmark'!$B$5:$B$46,E$34),"") | F36: =IFERROR(AVERAGEIFS('3_Master_Benchmark'!$P$5:$P$46,#REF!,$A36,'3_Master_Benchmark'!$B$5:$B$46,F$34),"") | G36: =IFERROR(AVERAGEIFS('3_Master_Benchmark'!$P$5:$P$46,#REF!,$A36,'3_Master_Benchmark'!$B$5:$B$46,G$34),"") | H36: =IFERROR(AVERAGEIFS('3_Master_Benchmark'!$P$5:$P$46,#REF!,$A36,'3_Master_Benchmark'!$B$5:$B$46,H$34),"") | I36: =IFERROR(AVERAGEIFS('3_Master_Benchmark'!$P$5:$P$46,#REF!,$A36,'3_Master_Benchmark'!$B$5:$B$46,I$34),"")
A37: 200-250 L | B37: =IFERROR(AVERAGEIFS('3_Master_Benchmark'!$P$5:$P$46,#REF!,$A37,'3_Master_Benchmark'!$B$5:$B$46,B$34),"") | C37: =IFERROR(AVERAGEIFS('3_Master_Benchmark'!$P$5:$P$46,#REF!,$A37,'3_Master_Benchmark'!$B$5:$B$46,C$34),"") | D37: =IFERROR(AVERAGEIFS('3_Master_Benchmark'!$P$5:$P$46,#REF!,$A37,'3_Master_Benchmark'!$B$5:$B$46,D$34),"") | E37: =IFERROR(AVERAGEIFS('3_Master_Benchmark'!$P$5:$P$46,#REF!,$A37,'3_Master_Benchmark'!$B$5:$B$46,E$34),"") | F37: =IFERROR(AVERAGEIFS('3_Master_Benchmark'!$P$5:$P$46,#REF!,$A37,'3_Master_Benchmark'!$B$5:$B$46,F$34),"") | G37: =IFERROR(AVERAGEIFS('3_Master_Benchmark'!$P$5:$P$46,#REF!,$A37,'3_Master_Benchmark'!$B$5:$B$46,G$34),"") | H37: =IFERROR(AVERAGEIFS('3_Master_Benchmark'!$P$5:$P$46,#REF!,$A37,'3_Master_Benchmark'!$B$5:$B$46,H$34),"") | I37: =IFERROR(AVERAGEIFS('3_Master_Benchmark'!$P$5:$P$46,#REF!,$A37,'3_Master_Benchmark'!$B$5:$B$46,I$34),"")
A38: 250-300 L | B38: =IFERROR(AVERAGEIFS('3_Master_Benchmark'!$P$5:$P$46,#REF!,$A38,'3_Master_Benchmark'!$B$5:$B$46,B$34),"") | C38: =IFERROR(AVERAGEIFS('3_Master_Benchmark'!$P$5:$P$46,#REF!,$A38,'3_Master_Benchmark'!$B$5:$B$46,C$34),"") | D38: =IFERROR(AVERAGEIFS('3_Master_Benchmark'!$P$5:$P$46,#REF!,$A38,'3_Master_Benchmark'!$B$5:$B$46,D$34),"") | E38: =IFERROR(AVERAGEIFS('3_Master_Benchmark'!$P$5:$P$46,#REF!,$A38,'3_Master_Benchmark'!$B$5:$B$46,E$34),"") | F38: =IFERROR(AVERAGEIFS('3_Master_Benchmark'!$P$5:$P$46,#REF!,$A38,'3_Master_Benchmark'!$B$5:$B$46,F$34),"") | G38: =IFERROR(AVERAGEIFS('3_Master_Benchmark'!$P$5:$P$46,#REF!,$A38,'3_Master_Benchmark'!$B$5:$B$46,G$34),"") | H38: =IFERROR(AVERAGEIFS('3_Master_Benchmark'!$P$5:$P$46,#REF!,$A38,'3_Master_Benchmark'!$B$5:$B$46,H$34),"") | I38: =IFERROR(AVERAGEIFS('3_Master_Benchmark'!$P$5:$P$46,#REF!,$A38,'3_Master_Benchmark'!$B$5:$B$46,I$34),"")
A39: 300-350 L | B39: =IFERROR(AVERAGEIFS('3_Master_Benchmark'!$P$5:$P$46,#REF!,$A39,'3_Master_Benchmark'!$B$5:$B$46,B$34),"") | C39: =IFERROR(AVERAGEIFS('3_Master_Benchmark'!$P$5:$P$46,#REF!,$A39,'3_Master_Benchmark'!$B$5:$B$46,C$34),"") | D39: =IFERROR(AVERAGEIFS('3_Master_Benchmark'!$P$5:$P$46,#REF!,$A39,'3_Master_Benchmark'!$B$5:$B$46,D$34),"") | E39: =IFERROR(AVERAGEIFS('3_Master_Benchmark'!$P$5:$P$46,#REF!,$A39,'3_Master_Benchmark'!$B$5:$B$46,E$34),"") | F39: =IFERROR(AVERAGEIFS('3_Master_Benchmark'!$P$5:$P$46,#REF!,$A39,'3_Master_Benchmark'!$B$5:$B$46,F$34),"") | G39: =IFERROR(AVERAGEIFS('3_Master_Benchmark'!$P$5:$P$46,#REF!,$A39,'3_Master_Benchmark'!$B$5:$B$46,G$34),"") | H39: =IFERROR(AVERAGEIFS('3_Master_Benchmark'!$P$5:$P$46,#REF!,$A39,'3_Master_Benchmark'!$B$5:$B$46,H$34),"") | I39: =IFERROR(AVERAGEIFS('3_Master_Benchmark'!$P$5:$P$46,#REF!,$A39,'3_Master_Benchmark'!$B$5:$B$46,I$34),"")
A40: 350-400 L | B40: =IFERROR(AVERAGEIFS('3_Master_Benchmark'!$P$5:$P$46,#REF!,$A40,'3_Master_Benchmark'!$B$5:$B$46,B$34),"") | C40: =IFERROR(AVERAGEIFS('3_Master_Benchmark'!$P$5:$P$46,#REF!,$A40,'3_Master_Benchmark'!$B$5:$B$46,C$34),"") | D40: =IFERROR(AVERAGEIFS('3_Master_Benchmark'!$P$5:$P$46,#REF!,$A40,'3_Master_Benchmark'!$B$5:$B$46,D$34),"") | E40: =IFERROR(AVERAGEIFS('3_Master_Benchmark'!$P$5:$P$46,#REF!,$A40,'3_Master_Benchmark'!$B$5:$B$46,E$34),"") | F40: =IFERROR(AVERAGEIFS('3_Master_Benchmark'!$P$5:$P$46,#REF!,$A40,'3_Master_Benchmark'!$B$5:$B$46,F$34),"") | G40: =IFERROR(AVERAGEIFS('3_Master_Benchmark'!$P$5:$P$46,#REF!,$A40,'3_Master_Benchmark'!$B$5:$B$46,G$34),"") | H40: =IFERROR(AVERAGEIFS('3_Master_Benchmark'!$P$5:$P$46,#REF!,$A40,'3_Master_Benchmark'!$B$5:$B$46,H$34),"") | I40: =IFERROR(AVERAGEIFS('3_Master_Benchmark'!$P$5:$P$46,#REF!,$A40,'3_Master_Benchmark'!$B$5:$B$46,I$34),"")
A41: 400-450 L | B41: =IFERROR(AVERAGEIFS('3_Master_Benchmark'!$P$5:$P$46,#REF!,$A41,'3_Master_Benchmark'!$B$5:$B$46,B$34),"") | C41: =IFERROR(AVERAGEIFS('3_Master_Benchmark'!$P$5:$P$46,#REF!,$A41,'3_Master_Benchmark'!$B$5:$B$46,C$34),"") | D41: =IFERROR(AVERAGEIFS('3_Master_Benchmark'!$P$5:$P$46,#REF!,$A41,'3_Master_Benchmark'!$B$5:$B$46,D$34),"") | E41: =IFERROR(AVERAGEIFS('3_Master_Benchmark'!$P$5:$P$46,#REF!,$A41,'3_Master_Benchmark'!$B$5:$B$46,E$34),"") | F41: =IFERROR(AVERAGEIFS('3_Master_Benchmark'!$P$5:$P$46,#REF!,$A41,'3_Master_Benchmark'!$B$5:$B$46,F$34),"") | G41: =IFERROR(AVERAGEIFS('3_Master_Benchmark'!$P$5:$P$46,#REF!,$A41,'3_Master_Benchmark'!$B$5:$B$46,G$34),"") | H41: =IFERROR(AVERAGEIFS('3_Master_Benchmark'!$P$5:$P$46,#REF!,$A41,'3_Master_Benchmark'!$B$5:$B$46,H$34),"") | I41: =IFERROR(AVERAGEIFS('3_Master_Benchmark'!$P$5:$P$46,#REF!,$A41,'3_Master_Benchmark'!$B$5:$B$46,I$34),"")
A42: 450-500 L | B42: =IFERROR(AVERAGEIFS('3_Master_Benchmark'!$P$5:$P$46,#REF!,$A42,'3_Master_Benchmark'!$B$5:$B$46,B$34),"") | C42: =IFERROR(AVERAGEIFS('3_Master_Benchmark'!$P$5:$P$46,#REF!,$A42,'3_Master_Benchmark'!$B$5:$B$46,C$34),"") | D42: =IFERROR(AVERAGEIFS('3_Master_Benchmark'!$P$5:$P$46,#REF!,$A42,'3_Master_Benchmark'!$B$5:$B$46,D$34),"") | E42: =IFERROR(AVERAGEIFS('3_Master_Benchmark'!$P$5:$P$46,#REF!,$A42,'3_Master_Benchmark'!$B$5:$B$46,E$34),"") | F42: =IFERROR(AVERAGEIFS('3_Master_Benchmark'!$P$5:$P$46,#REF!,$A42,'3_Master_Benchmark'!$B$5:$B$46,F$34),"") | G42: =IFERROR(AVERAGEIFS('3_Master_Benchmark'!$P$5:$P$46,#REF!,$A42,'3_Master_Benchmark'!$B$5:$B$46,G$34),"") | H42: =IFERROR(AVERAGEIFS('3_Master_Benchmark'!$P$5:$P$46,#REF!,$A42,'3_Master_Benchmark'!$B$5:$B$46,H$34),"") | I42: =IFERROR(AVERAGEIFS('3_Master_Benchmark'!$P$5:$P$46,#REF!,$A42,'3_Master_Benchmark'!$B$5:$B$46,I$34),"")
A43: 500-550 L | B43: =IFERROR(AVERAGEIFS('3_Master_Benchmark'!$P$5:$P$46,#REF!,$A43,'3_Master_Benchmark'!$B$5:$B$46,B$34),"") | C43: =IFERROR(AVERAGEIFS('3_Master_Benchmark'!$P$5:$P$46,#REF!,$A43,'3_Master_Benchmark'!$B$5:$B$46,C$34),"") | D43: =IFERROR(AVERAGEIFS('3_Master_Benchmark'!$P$5:$P$46,#REF!,$A43,'3_Master_Benchmark'!$B$5:$B$46,D$34),"") | E43: =IFERROR(AVERAGEIFS('3_Master_Benchmark'!$P$5:$P$46,#REF!,$A43,'3_Master_Benchmark'!$B$5:$B$46,E$34),"") | F43: =IFERROR(AVERAGEIFS('3_Master_Benchmark'!$P$5:$P$46,#REF!,$A43,'3_Master_Benchmark'!$B$5:$B$46,F$34),"") | G43: =IFERROR(AVERAGEIFS('3_Master_Benchmark'!$P$5:$P$46,#REF!,$A43,'3_Master_Benchmark'!$B$5:$B$46,G$34),"") | H43: =IFERROR(AVERAGEIFS('3_Master_Benchmark'!$P$5:$P$46,#REF!,$A43,'3_Master_Benchmark'!$B$5:$B$46,H$34),"") | I43: =IFERROR(AVERAGEIFS('3_Master_Benchmark'!$P$5:$P$46,#REF!,$A43,'3_Master_Benchmark'!$B$5:$B$46,I$34),"")
A44: 550-600 L | B44: =IFERROR(AVERAGEIFS('3_Master_Benchmark'!$P$5:$P$46,#REF!,$A44,'3_Master_Benchmark'!$B$5:$B$46,B$34),"") | C44: =IFERROR(AVERAGEIFS('3_Master_Benchmark'!$P$5:$P$46,#REF!,$A44,'3_Master_Benchmark'!$B$5:$B$46,C$34),"") | D44: =IFERROR(AVERAGEIFS('3_Master_Benchmark'!$P$5:$P$46,#REF!,$A44,'3_Master_Benchmark'!$B$5:$B$46,D$34),"") | E44: =IFERROR(AVERAGEIFS('3_Master_Benchmark'!$P$5:$P$46,#REF!,$A44,'3_Master_Benchmark'!$B$5:$B$46,E$34),"") | F44: =IFERROR(AVERAGEIFS('3_Master_Benchmark'!$P$5:$P$46,#REF!,$A44,'3_Master_Benchmark'!$B$5:$B$46,F$34),"") | G44: =IFERROR(AVERAGEIFS('3_Master_Benchmark'!$P$5:$P$46,#REF!,$A44,'3_Master_Benchmark'!$B$5:$B$46,G$34),"") | H44: =IFERROR(AVERAGEIFS('3_Master_Benchmark'!$P$5:$P$46,#REF!,$A44,'3_Master_Benchmark'!$B$5:$B$46,H$34),"") | I44: =IFERROR(AVERAGEIFS('3_Master_Benchmark'!$P$5:$P$46,#REF!,$A44,'3_Master_Benchmark'!$B$5:$B$46,I$34),"")
A45: 600-650 L | B45: =IFERROR(AVERAGEIFS('3_Master_Benchmark'!$P$5:$P$46,#REF!,$A45,'3_Master_Benchmark'!$B$5:$B$46,B$34),"") | C45: =IFERROR(AVERAGEIFS('3_Master_Benchmark'!$P$5:$P$46,#REF!,$A45,'3_Master_Benchmark'!$B$5:$B$46,C$34),"") | D45: =IFERROR(AVERAGEIFS('3_Master_Benchmark'!$P$5:$P$46,#REF!,$A45,'3_Master_Benchmark'!$B$5:$B$46,D$34),"") | E45: =IFERROR(AVERAGEIFS('3_Master_Benchmark'!$P$5:$P$46,#REF!,$A45,'3_Master_Benchmark'!$B$5:$B$46,E$34),"") | F45: =IFERROR(AVERAGEIFS('3_Master_Benchmark'!$P$5:$P$46,#REF!,$A45,'3_Master_Benchmark'!$B$5:$B$46,F$34),"") | G45: =IFERROR(AVERAGEIFS('3_Master_Benchmark'!$P$5:$P$46,#REF!,$A45,'3_Master_Benchmark'!$B$5:$B$46,G$34),"") | H45: =IFERROR(AVERAGEIFS('3_Master_Benchmark'!$P$5:$P$46,#REF!,$A45,'3_Master_Benchmark'!$B$5:$B$46,H$34),"") | I45: =IFERROR(AVERAGEIFS('3_Master_Benchmark'!$P$5:$P$46,#REF!,$A45,'3_Master_Benchmark'!$B$5:$B$46,I$34),"")
...

Sheet 5_Harga_Channel
A1: ANALISIS HARGA PER CHANNEL
A2: Tujuan: melihat apakah harga kita konsisten antar channel. Spread besar = risiko konflik channel dan kebingungan konsumen.
A4: TABEL A — HARGA RATA-RATA per BRAND per CHANNEL (Rp)
A5: Sel kosong = brand tersebut belum ada datanya di channel itu. Prioritaskan pengisian kolom yang masih kosong.
A6: Brand | B6: MODERN - UFO Elektronika | C6: MODERN - Hartono | D6: TRADISIONAL - Candi Bantas Pos | E6: TRADISIONAL - Pondok Elektronik | F6: ONLINE - E-commerce | G6: Jml SKU Terdata
A7: Haier | B7: =IFERROR(AVERAGEIFS('3_Master_Benchmark'!$K$5:$K$46,'3_Master_Benchmark'!$B$5:$B$46,$A7),"") -> 19249000 | C7: =IFERROR(AVERAGEIFS('3_Master_Benchmark'!$L$5:$L$46,'3_Master_Benchmark'!$B$5:$B$46,$A7),"") | D7: =IFERROR(AVERAGEIFS('3_Master_Benchmark'!$M$5:$M$46,'3_Master_Benchmark'!$B$5:$B$46,$A7),"") | E7: =IFERROR(AVERAGEIFS('3_Master_Benchmark'!$N$5:$N$46,'3_Master_Benchmark'!$B$5:$B$46,$A7),"") | F7: =IFERROR(AVERAGEIFS('3_Master_Benchmark'!$O$5:$O$46,'3_Master_Benchmark'!$B$5:$B$46,$A7),"") | G7: =COUNTIFS('3_Master_Benchmark'!$B$5:$B$46,$A7) -> 9
A8: AQUA | B8: =IFERROR(AVERAGEIFS('3_Master_Benchmark'!$K$5:$K$46,'3_Master_Benchmark'!$B$5:$B$46,$A8),"") | C8: =IFERROR(AVERAGEIFS('3_Master_Benchmark'!$L$5:$L$46,'3_Master_Benchmark'!$B$5:$B$46,$A8),"") | D8: =IFERROR(AVERAGEIFS('3_Master_Benchmark'!$M$5:$M$46,'3_Master_Benchmark'!$B$5:$B$46,$A8),"") | E8: =IFERROR(AVERAGEIFS('3_Master_Benchmark'!$N$5:$N$46,'3_Master_Benchmark'!$B$5:$B$46,$A8),"") | F8: =IFERROR(AVERAGEIFS('3_Master_Benchmark'!$O$5:$O$46,'3_Master_Benchmark'!$B$5:$B$46,$A8),"") | G8: =COUNTIFS('3_Master_Benchmark'!$B$5:$B$46,$A8) -> 2
A9: Sharp | B9: =IFERROR(AVERAGEIFS('3_Master_Benchmark'!$K$5:$K$46,'3_Master_Benchmark'!$B$5:$B$46,$A9),"") | C9: =IFERROR(AVERAGEIFS('3_Master_Benchmark'!$L$5:$L$46,'3_Master_Benchmark'!$B$5:$B$46,$A9),"") | D9: =IFERROR(AVERAGEIFS('3_Master_Benchmark'!$M$5:$M$46,'3_Master_Benchmark'!$B$5:$B$46,$A9),"") | E9: =IFERROR(AVERAGEIFS('3_Master_Benchmark'!$N$5:$N$46,'3_Master_Benchmark'!$B$5:$B$46,$A9),"") | F9: =IFERROR(AVERAGEIFS('3_Master_Benchmark'!$O$5:$O$46,'3_Master_Benchmark'!$B$5:$B$46,$A9),"") -> 9969498.1 | G9: =COUNTIFS('3_Master_Benchmark'!$B$5:$B$46,$A9) -> 10
A10: LG | B10: =IFERROR(AVERAGEIFS('3_Master_Benchmark'!$K$5:$K$46,'3_Master_Benchmark'!$B$5:$B$46,$A10),"") | C10: =IFERROR(AVERAGEIFS('3_Master_Benchmark'!$L$5:$L$46,'3_Master_Benchmark'!$B$5:$B$46,$A10),"") | D10: =IFERROR(AVERAGEIFS('3_Master_Benchmark'!$M$5:$M$46,'3_Master_Benchmark'!$B$5:$B$46,$A10),"") | E10: =IFERROR(AVERAGEIFS('3_Master_Benchmark'!$N$5:$N$46,'3_Master_Benchmark'!$B$5:$B$46,$A10),"") | F10: =IFERROR(AVERAGEIFS('3_Master_Benchmark'!$O$5:$O$46,'3_Master_Benchmark'!$B$5:$B$46,$A10),"") -> 10002668 | G10: =COUNTIFS('3_Master_Benchmark'!$B$5:$B$46,$A10) -> 6
A11: Samsung | B11: =IFERROR(AVERAGEIFS('3_Master_Benchmark'!$K$5:$K$46,'3_Master_Benchmark'!$B$5:$B$46,$A11),"") | C11: =IFERROR(AVERAGEIFS('3_Master_Benchmark'!$L$5:$L$46,'3_Master_Benchmark'!$B$5:$B$46,$A11),"") | D11: =IFERROR(AVERAGEIFS('3_Master_Benchmark'!$M$5:$M$46,'3_Master_Benchmark'!$B$5:$B$46,$A11),"") | E11: =IFERROR(AVERAGEIFS('3_Master_Benchmark'!$N$5:$N$46,'3_Master_Benchmark'!$B$5:$B$46,$A11),"") | F11: =IFERROR(AVERAGEIFS('3_Master_Benchmark'!$O$5:$O$46,'3_Master_Benchmark'!$B$5:$B$46,$A11),"") -> 13682908 | G11: =COUNTIFS('3_Master_Benchmark'!$B$5:$B$46,$A11) -> 5
A12: Midea | B12: =IFERROR(AVERAGEIFS('3_Master_Benchmark'!$K$5:$K$46,'3_Master_Benchmark'!$B$5:$B$46,$A12),"") | C12: =IFERROR(AVERAGEIFS('3_Master_Benchmark'!$L$5:$L$46,'3_Master_Benchmark'!$B$5:$B$46,$A12),"") | D12: =IFERROR(AVERAGEIFS('3_Master_Benchmark'!$M$5:$M$46,'3_Master_Benchmark'!$B$5:$B$46,$A12),"") | E12: =IFERROR(AVERAGEIFS('3_Master_Benchmark'!$N$5:$N$46,'3_Master_Benchmark'!$B$5:$B$46,$A12),"") | F12: =IFERROR(AVERAGEIFS('3_Master_Benchmark'!$O$5:$O$46,'3_Master_Benchmark'!$B$5:$B$46,$A12),"") -> 4750000 | G12: =COUNTIFS('3_Master_Benchmark'!$B$5:$B$46,$A12) -> 2
A13: Polytron | B13: =IFERROR(AVERAGEIFS('3_Master_Benchmark'!$K$5:$K$46,'3_Master_Benchmark'!$B$5:$B$46,$A13),"") | C13: =IFERROR(AVERAGEIFS('3_Master_Benchmark'!$L$5:$L$46,'3_Master_Benchmark'!$B$5:$B$46,$A13),"") | D13: =IFERROR(AVERAGEIFS('3_Master_Benchmark'!$M$5:$M$46,'3_Master_Benchmark'!$B$5:$B$46,$A13),"") | E13: =IFERROR(AVERAGEIFS('3_Master_Benchmark'!$N$5:$N$46,'3_Master_Benchmark'!$B$5:$B$46,$A13),"") | F13: =IFERROR(AVERAGEIFS('3_Master_Benchmark'!$O$5:$O$46,'3_Master_Benchmark'!$B$5:$B$46,$A13),"") -> 3356122 | G13: =COUNTIFS('3_Master_Benchmark'!$B$5:$B$46,$A13) -> 1
A14: Electrolux | B14: =IFERROR(AVERAGEIFS('3_Master_Benchmark'!$K$5:$K$46,'3_Master_Benchmark'!$B$5:$B$46,$A14),"") | C14: =IFERROR(AVERAGEIFS('3_Master_Benchmark'!$L$5:$L$46,'3_Master_Benchmark'!$B$5:$B$46,$A14),"") | D14: =IFERROR(AVERAGEIFS('3_Master_Benchmark'!$M$5:$M$46,'3_Master_Benchmark'!$B$5:$B$46,$A14),"") | E14: =IFERROR(AVERAGEIFS('3_Master_Benchmark'!$N$5:$N$46,'3_Master_Benchmark'!$B$5:$B$46,$A14),"") | F14: =IFERROR(AVERAGEIFS('3_Master_Benchmark'!$O$5:$O$46,'3_Master_Benchmark'!$B$5:$B$46,$A14),"") | G14: =COUNTIFS('3_Master_Benchmark'!$B$5:$B$46,$A14) -> 3
A17: TABEL B — KONSISTENSI HARGA ANTAR CHANNEL
A18: Spread = (harga tertinggi - terendah) / terendah. Di atas 10% biasanya memicu keluhan dealer dan tawar-menawar konsumen.
A19: Brand | B19: Rata-rata Spread Antar-Channel | C19: SKU dengan Spread > 10% | D19: Jml SKU Terdata >1 Channel
A20: Haier | B20: =IFERROR(AVERAGEIFS(#REF!,'3_Master_Benchmark'!$B$5:$B$46,$A20),"") | C20: =COUNTIFS('3_Master_Benchmark'!$B$5:$B$46,$A20,#REF!,">0.1") -> #VALUE! | D20: =COUNTIFS('3_Master_Benchmark'!$B$5:$B$46,$A20,#REF!,">1") -> #VALUE!
A21: AQUA | B21: =IFERROR(AVERAGEIFS(#REF!,'3_Master_Benchmark'!$B$5:$B$46,$A21),"") | C21: =COUNTIFS('3_Master_Benchmark'!$B$5:$B$46,$A21,#REF!,">0.1") -> #VALUE! | D21: =COUNTIFS('3_Master_Benchmark'!$B$5:$B$46,$A21,#REF!,">1") -> #VALUE!
A22: Sharp | B22: =IFERROR(AVERAGEIFS(#REF!,'3_Master_Benchmark'!$B$5:$B$46,$A22),"") | C22: =COUNTIFS('3_Master_Benchmark'!$B$5:$B$46,$A22,#REF!,">0.1") -> #VALUE! | D22: =COUNTIFS('3_Master_Benchmark'!$B$5:$B$46,$A22,#REF!,">1") -> #VALUE!
A23: LG | B23: =IFERROR(AVERAGEIFS(#REF!,'3_Master_Benchmark'!$B$5:$B$46,$A23),"") | C23: =COUNTIFS('3_Master_Benchmark'!$B$5:$B$46,$A23,#REF!,">0.1") -> #VALUE! | D23: =COUNTIFS('3_Master_Benchmark'!$B$5:$B$46,$A23,#REF!,">1") -> #VALUE!
A24: Samsung | B24: =IFERROR(AVERAGEIFS(#REF!,'3_Master_Benchmark'!$B$5:$B$46,$A24),"") | C24: =COUNTIFS('3_Master_Benchmark'!$B$5:$B$46,$A24,#REF!,">0.1") -> #VALUE! | D24: =COUNTIFS('3_Master_Benchmark'!$B$5:$B$46,$A24,#REF!,">1") -> #VALUE!
A25: Midea | B25: =IFERROR(AVERAGEIFS(#REF!,'3_Master_Benchmark'!$B$5:$B$46,$A25),"") | C25: =COUNTIFS('3_Master_Benchmark'!$B$5:$B$46,$A25,#REF!,">0.1") -> #VALUE! | D25: =COUNTIFS('3_Master_Benchmark'!$B$5:$B$46,$A25,#REF!,">1") -> #VALUE!
A26: Polytron | B26: =IFERROR(AVERAGEIFS(#REF!,'3_Master_Benchmark'!$B$5:$B$46,$A26),"") | C26: =COUNTIFS('3_Master_Benchmark'!$B$5:$B$46,$A26,#REF!,">0.1") -> #VALUE! | D26: =COUNTIFS('3_Master_Benchmark'!$B$5:$B$46,$A26,#REF!,">1") -> #VALUE!
A27: Electrolux | B27: =IFERROR(AVERAGEIFS(#REF!,'3_Master_Benchmark'!$B$5:$B$46,$A27),"") | C27: =COUNTIFS('3_Master_Benchmark'!$B$5:$B$46,$A27,#REF!,">0.1") -> #VALUE! | D27: =COUNTIFS('3_Master_Benchmark'!$B$5:$B$46,$A27,#REF!,">1") -> #VALUE!
A30: STATUS KELENGKAPAN DATA — apa yang harus dikumpulkan sebelum presentasi berikutnya
A31: Channel | B31: Jml SKU Terisi | C31: Total SKU di Master | D31: % Kelengkapan
A32: MODERN - UFO Elektronika | B32: =COUNT('3_Master_Benchmark'!$K$5:$K$46) -> 8 | C32: =COUNTA('3_Master_Benchmark'!$B$5:$B$46) -> 42 | D32: =IFERROR($B32/$C32,"") -> 0.19047619
A33: MODERN - Hartono | B33: =COUNT('3_Master_Benchmark'!$L$5:$L$46) -> 0 | C33: =COUNTA('3_Master_Benchmark'!$B$5:$B$46) -> 42 | D33: =IFERROR($B33/$C33,"") -> 0
A34: TRADISIONAL - Candi Bantas Pos | B34: =COUNT('3_Master_Benchmark'!$M$5:$M$46) -> 0 | C34: =COUNTA('3_Master_Benchmark'!$B$5:$B$46) -> 42 | D34: =IFERROR($B34/$C34,"") -> 0
A35: TRADISIONAL - Pondok Elektronik | B35: =COUNT('3_Master_Benchmark'!$N$5:$N$46) -> 0 | C35: =COUNTA('3_Master_Benchmark'!$B$5:$B$46) -> 42 | D35: =IFERROR($B35/$C35,"") -> 0
A36: ONLINE - E-commerce | B36: =COUNT('3_Master_Benchmark'!$O$5:$O$46) -> 23 | C36: =COUNTA('3_Master_Benchmark'!$B$5:$B$46) -> 42 | D36: =IFERROR($B36/$C36,"") -> 0.54761905
